2020-11-20 15:11:20 WARNING (MainThread) [homeassistant.loader] You are using a custom integration for hacs which has not been tested by Home Assistant. This component might cause stability problems, be sure to disable it if you experience issues with Home Assistant.
2020-11-20 15:19:00 ERROR (MainThread) [homeassistant] Error doing job: Unclosed connection
2020-11-20 15:22:43 ERROR (MainThread) [homeassistant] Error doing job: Unclosed connection
2020-11-20 17:21:05 ERROR (MainThread) [frontend.js.latest.202010214] :0:0 Script error.
2020-11-20 17:49:04 ERROR (SyncWorker_54) [homeassistant.components.yeelight] Unable to update device 192.168.1.3, yeelight_ceiling1_0x0000000007c50fc5: Bulb closed the connection.
2020-11-20 17:50:02 ERROR (SyncWorker_48) [homeassistant.components.yeelight] Unable to update device 192.168.1.4, 燈3: Bulb closed the connection.
2020-11-20 17:50:02 ERROR (SyncWorker_49) [homeassistant.components.yeelight] Unable to update device 192.168.1.5, yeelight_ceiling1_0x0000000007c51949: Bulb closed the connection.
2020-11-20 17:50:04 ERROR (SyncWorker_56) [homeassistant.components.yeelight] Unable to update device 192.168.1.3, yeelight_ceiling1_0x0000000007c50fc5: Bulb closed the connection.
2020-11-20 17:50:23 ERROR (MainThread) [homeassistant.components.upnp] Timeout fetching RBR50 (Gateway) data
2020-11-20 17:50:40 ERROR (MainThread) [homeassistant.components.ipp] Error fetching ipp data: Invalid response from API: Error occurred while communicating with IPP server.
2020-11-20 17:51:33 WARNING (MainThread) [homeassistant.components.homekit_controller.connection] HomeKit controller update skipped as previous poll still in flight
2020-11-20 17:51:34 ERROR (MainThread) [homeassistant] Error doing job: Task exception was never retrieved
Traceback (most recent call last):
  File "/usr/src/homeassistant/homeassistant/components/homekit_controller/connection.py", line 376, in async_update
    self.process_new_events(new_values_dict)
  File "/usr/src/homeassistant/homeassistant/components/homekit_controller/connection.py", line 393, in process_new_events
    self.entity_map.process_changes(new_values_dict)
  File "/usr/local/lib/python3.8/site-packages/aiohomekit/model/__init__.py", line 281, in process_changes
    accessory = self.aid(aid)
  File "/usr/local/lib/python3.8/site-packages/aiohomekit/model/__init__.py", line 277, in aid
    return next(filter(lambda accessory: accessory.aid == aid, self.accessories))
StopIteration

The above exception was the direct cause of the following exception:

Traceback (most recent call last):
  File "/usr/src/homeassistant/homeassistant/components/homekit_controller/connection.py", line 249, in async_process_entity_map
    await self.async_update()
RuntimeError: coroutine raised StopIteration
2020-11-20 17:52:32 ERROR (SyncWorker_56) [homeassistant.components.yeelight] Unable to update device 192.168.1.5, yeelight_ceiling1_0x0000000007c51949: Bulb closed the connection.
2020-11-20 17:52:32 ERROR (SyncWorker_10) [homeassistant.components.yeelight] Unable to update device 192.168.1.4, 燈3: Bulb closed the connection.
2020-11-20 17:52:33 ERROR (MainThread) [homeassistant.components.upnp] Timeout fetching RBR50 (Gateway) data
2020-11-20 17:52:34 ERROR (SyncWorker_36) [homeassistant.components.yeelight] Unable to update device 192.168.1.3, yeelight_ceiling1_0x0000000007c50fc5: Bulb closed the connection.
2020-11-20 17:52:34 ERROR (MainThread) [homeassistant] Error doing job: Task exception was never retrieved
Traceback (most recent call last):
  File "/usr/src/homeassistant/homeassistant/components/homekit_controller/connection.py", line 376, in async_update
    self.process_new_events(new_values_dict)
  File "/usr/src/homeassistant/homeassistant/components/homekit_controller/connection.py", line 393, in process_new_events
    self.entity_map.process_changes(new_values_dict)
  File "/usr/local/lib/python3.8/site-packages/aiohomekit/model/__init__.py", line 281, in process_changes
    accessory = self.aid(aid)
  File "/usr/local/lib/python3.8/site-packages/aiohomekit/model/__init__.py", line 277, in aid
    return next(filter(lambda accessory: accessory.aid == aid, self.accessories))
StopIteration

The above exception was the direct cause of the following exception:

RuntimeError: coroutine raised StopIteration
2020-11-20 17:53:34 ERROR (MainThread) [homeassistant] Error doing job: Task exception was never retrieved
Traceback (most recent call last):
  File "/usr/src/homeassistant/homeassistant/components/homekit_controller/connection.py", line 376, in async_update
    self.process_new_events(new_values_dict)
  File "/usr/src/homeassistant/homeassistant/components/homekit_controller/connection.py", line 393, in process_new_events
    self.entity_map.process_changes(new_values_dict)
  File "/usr/local/lib/python3.8/site-packages/aiohomekit/model/__init__.py", line 281, in process_changes
    accessory = self.aid(aid)
  File "/usr/local/lib/python3.8/site-packages/aiohomekit/model/__init__.py", line 277, in aid
    return next(filter(lambda accessory: accessory.aid == aid, self.accessories))
StopIteration

The above exception was the direct cause of the following exception:

RuntimeError: coroutine raised StopIteration
2020-11-20 17:54:34 ERROR (MainThread) [homeassistant] Error doing job: Task exception was never retrieved
Traceback (most recent call last):
  File "/usr/src/homeassistant/homeassistant/components/homekit_controller/connection.py", line 376, in async_update
    self.process_new_events(new_values_dict)
  File "/usr/src/homeassistant/homeassistant/components/homekit_controller/connection.py", line 393, in process_new_events
    self.entity_map.process_changes(new_values_dict)
  File "/usr/local/lib/python3.8/site-packages/aiohomekit/model/__init__.py", line 281, in process_changes
    accessory = self.aid(aid)
  File "/usr/local/lib/python3.8/site-packages/aiohomekit/model/__init__.py", line 277, in aid
    return next(filter(lambda accessory: accessory.aid == aid, self.accessories))
StopIteration

The above exception was the direct cause of the following exception:

RuntimeError: coroutine raised StopIteration
2020-11-20 17:55:34 ERROR (MainThread) [homeassistant] Error doing job: Task exception was never retrieved
Traceback (most recent call last):
  File "/usr/src/homeassistant/homeassistant/components/homekit_controller/connection.py", line 376, in async_update
    self.process_new_events(new_values_dict)
  File "/usr/src/homeassistant/homeassistant/components/homekit_controller/connection.py", line 393, in process_new_events
    self.entity_map.process_changes(new_values_dict)
  File "/usr/local/lib/python3.8/site-packages/aiohomekit/model/__init__.py", line 281, in process_changes
    accessory = self.aid(aid)
  File "/usr/local/lib/python3.8/site-packages/aiohomekit/model/__init__.py", line 277, in aid
    return next(filter(lambda accessory: accessory.aid == aid, self.accessories))
StopIteration

The above exception was the direct cause of the following exception:

RuntimeError: coroutine raised StopIteration
2020-11-20 17:56:34 ERROR (MainThread) [homeassistant] Error doing job: Task exception was never retrieved
Traceback (most recent call last):
  File "/usr/src/homeassistant/homeassistant/components/homekit_controller/connection.py", line 376, in async_update
    self.process_new_events(new_values_dict)
  File "/usr/src/homeassistant/homeassistant/components/homekit_controller/connection.py", line 393, in process_new_events
    self.entity_map.process_changes(new_values_dict)
  File "/usr/local/lib/python3.8/site-packages/aiohomekit/model/__init__.py", line 281, in process_changes
    accessory = self.aid(aid)
  File "/usr/local/lib/python3.8/site-packages/aiohomekit/model/__init__.py", line 277, in aid
    return next(filter(lambda accessory: accessory.aid == aid, self.accessories))
StopIteration

The above exception was the direct cause of the following exception:

RuntimeError: coroutine raised StopIteration
2020-11-20 17:57:34 ERROR (MainThread) [homeassistant] Error doing job: Task exception was never retrieved
Traceback (most recent call last):
  File "/usr/src/homeassistant/homeassistant/components/homekit_controller/connection.py", line 376, in async_update
    self.process_new_events(new_values_dict)
  File "/usr/src/homeassistant/homeassistant/components/homekit_controller/connection.py", line 393, in process_new_events
    self.entity_map.process_changes(new_values_dict)
  File "/usr/local/lib/python3.8/site-packages/aiohomekit/model/__init__.py", line 281, in process_changes
    accessory = self.aid(aid)
  File "/usr/local/lib/python3.8/site-packages/aiohomekit/model/__init__.py", line 277, in aid
    return next(filter(lambda accessory: accessory.aid == aid, self.accessories))
StopIteration

The above exception was the direct cause of the following exception:

RuntimeError: coroutine raised StopIteration
2020-11-20 17:58:34 ERROR (MainThread) [homeassistant] Error doing job: Task exception was never retrieved
Traceback (most recent call last):
  File "/usr/src/homeassistant/homeassistant/components/homekit_controller/connection.py", line 376, in async_update
    self.process_new_events(new_values_dict)
  File "/usr/src/homeassistant/homeassistant/components/homekit_controller/connection.py", line 393, in process_new_events
    self.entity_map.process_changes(new_values_dict)
  File "/usr/local/lib/python3.8/site-packages/aiohomekit/model/__init__.py", line 281, in process_changes
    accessory = self.aid(aid)
  File "/usr/local/lib/python3.8/site-packages/aiohomekit/model/__init__.py", line 277, in aid
    return next(filter(lambda accessory: accessory.aid == aid, self.accessories))
StopIteration

The above exception was the direct cause of the following exception:

RuntimeError: coroutine raised StopIteration
2020-11-20 17:59:34 ERROR (MainThread) [homeassistant] Error doing job: Task exception was never retrieved
Traceback (most recent call last):
  File "/usr/src/homeassistant/homeassistant/components/homekit_controller/connection.py", line 376, in async_update
    self.process_new_events(new_values_dict)
  File "/usr/src/homeassistant/homeassistant/components/homekit_controller/connection.py", line 393, in process_new_events
    self.entity_map.process_changes(new_values_dict)
  File "/usr/local/lib/python3.8/site-packages/aiohomekit/model/__init__.py", line 281, in process_changes
    accessory = self.aid(aid)
  File "/usr/local/lib/python3.8/site-packages/aiohomekit/model/__init__.py", line 277, in aid
    return next(filter(lambda accessory: accessory.aid == aid, self.accessories))
StopIteration

The above exception was the direct cause of the following exception:

RuntimeError: coroutine raised StopIteration
2020-11-20 18:00:34 ERROR (MainThread) [homeassistant] Error doing job: Task exception was never retrieved
Traceback (most recent call last):
  File "/usr/src/homeassistant/homeassistant/components/homekit_controller/connection.py", line 376, in async_update
    self.process_new_events(new_values_dict)
  File "/usr/src/homeassistant/homeassistant/components/homekit_controller/connection.py", line 393, in process_new_events
    self.entity_map.process_changes(new_values_dict)
  File "/usr/local/lib/python3.8/site-packages/aiohomekit/model/__init__.py", line 281, in process_changes
    accessory = self.aid(aid)
  File "/usr/local/lib/python3.8/site-packages/aiohomekit/model/__init__.py", line 277, in aid
    return next(filter(lambda accessory: accessory.aid == aid, self.accessories))
StopIteration

The above exception was the direct cause of the following exception:

RuntimeError: coroutine raised StopIteration
2020-11-20 18:01:34 ERROR (MainThread) [homeassistant] Error doing job: Task exception was never retrieved
Traceback (most recent call last):
  File "/usr/src/homeassistant/homeassistant/components/homekit_controller/connection.py", line 376, in async_update
    self.process_new_events(new_values_dict)
  File "/usr/src/homeassistant/homeassistant/components/homekit_controller/connection.py", line 393, in process_new_events
    self.entity_map.process_changes(new_values_dict)
  File "/usr/local/lib/python3.8/site-packages/aiohomekit/model/__init__.py", line 281, in process_changes
    accessory = self.aid(aid)
  File "/usr/local/lib/python3.8/site-packages/aiohomekit/model/__init__.py", line 277, in aid
    return next(filter(lambda accessory: accessory.aid == aid, self.accessories))
StopIteration

The above exception was the direct cause of the following exception:

RuntimeError: coroutine raised StopIteration
2020-11-20 18:02:34 ERROR (MainThread) [homeassistant] Error doing job: Task exception was never retrieved
Traceback (most recent call last):
  File "/usr/src/homeassistant/homeassistant/components/homekit_controller/connection.py", line 376, in async_update
    self.process_new_events(new_values_dict)
  File "/usr/src/homeassistant/homeassistant/components/homekit_controller/connection.py", line 393, in process_new_events
    self.entity_map.process_changes(new_values_dict)
  File "/usr/local/lib/python3.8/site-packages/aiohomekit/model/__init__.py", line 281, in process_changes
    accessory = self.aid(aid)
  File "/usr/local/lib/python3.8/site-packages/aiohomekit/model/__init__.py", line 277, in aid
    return next(filter(lambda accessory: accessory.aid == aid, self.accessories))
StopIteration

The above exception was the direct cause of the following exception:

RuntimeError: coroutine raised StopIteration
2020-11-20 18:03:34 ERROR (MainThread) [homeassistant] Error doing job: Task exception was never retrieved
Traceback (most recent call last):
  File "/usr/src/homeassistant/homeassistant/components/homekit_controller/connection.py", line 376, in async_update
    self.process_new_events(new_values_dict)
  File "/usr/src/homeassistant/homeassistant/components/homekit_controller/connection.py", line 393, in process_new_events
    self.entity_map.process_changes(new_values_dict)
  File "/usr/local/lib/python3.8/site-packages/aiohomekit/model/__init__.py", line 281, in process_changes
    accessory = self.aid(aid)
  File "/usr/local/lib/python3.8/site-packages/aiohomekit/model/__init__.py", line 277, in aid
    return next(filter(lambda accessory: accessory.aid == aid, self.accessories))
StopIteration

The above exception was the direct cause of the following exception:

RuntimeError: coroutine raised StopIteration
2020-11-20 18:04:34 ERROR (MainThread) [homeassistant] Error doing job: Task exception was never retrieved
Traceback (most recent call last):
  File "/usr/src/homeassistant/homeassistant/components/homekit_controller/connection.py", line 376, in async_update
    self.process_new_events(new_values_dict)
  File "/usr/src/homeassistant/homeassistant/components/homekit_controller/connection.py", line 393, in process_new_events
    self.entity_map.process_changes(new_values_dict)
  File "/usr/local/lib/python3.8/site-packages/aiohomekit/model/__init__.py", line 281, in process_changes
    accessory = self.aid(aid)
  File "/usr/local/lib/python3.8/site-packages/aiohomekit/model/__init__.py", line 277, in aid
    return next(filter(lambda accessory: accessory.aid == aid, self.accessories))
StopIteration

The above exception was the direct cause of the following exception:

RuntimeError: coroutine raised StopIteration
2020-11-20 18:05:34 ERROR (MainThread) [homeassistant] Error doing job: Task exception was never retrieved
Traceback (most recent call last):
  File "/usr/src/homeassistant/homeassistant/components/homekit_controller/connection.py", line 376, in async_update
    self.process_new_events(new_values_dict)
  File "/usr/src/homeassistant/homeassistant/components/homekit_controller/connection.py", line 393, in process_new_events
    self.entity_map.process_changes(new_values_dict)
  File "/usr/local/lib/python3.8/site-packages/aiohomekit/model/__init__.py", line 281, in process_changes
    accessory = self.aid(aid)
  File "/usr/local/lib/python3.8/site-packages/aiohomekit/model/__init__.py", line 277, in aid
    return next(filter(lambda accessory: accessory.aid == aid, self.accessories))
StopIteration

The above exception was the direct cause of the following exception:

RuntimeError: coroutine raised StopIteration
2020-11-20 18:06:34 ERROR (MainThread) [homeassistant] Error doing job: Task exception was never retrieved
Traceback (most recent call last):
  File "/usr/src/homeassistant/homeassistant/components/homekit_controller/connection.py", line 376, in async_update
    self.process_new_events(new_values_dict)
  File "/usr/src/homeassistant/homeassistant/components/homekit_controller/connection.py", line 393, in process_new_events
    self.entity_map.process_changes(new_values_dict)
  File "/usr/local/lib/python3.8/site-packages/aiohomekit/model/__init__.py", line 281, in process_changes
    accessory = self.aid(aid)
  File "/usr/local/lib/python3.8/site-packages/aiohomekit/model/__init__.py", line 277, in aid
    return next(filter(lambda accessory: accessory.aid == aid, self.accessories))
StopIteration

The above exception was the direct cause of the following exception:

RuntimeError: coroutine raised StopIteration
2020-11-20 18:07:34 ERROR (MainThread) [homeassistant] Error doing job: Task exception was never retrieved
Traceback (most recent call last):
  File "/usr/src/homeassistant/homeassistant/components/homekit_controller/connection.py", line 376, in async_update
    self.process_new_events(new_values_dict)
  File "/usr/src/homeassistant/homeassistant/components/homekit_controller/connection.py", line 393, in process_new_events
    self.entity_map.process_changes(new_values_dict)
  File "/usr/local/lib/python3.8/site-packages/aiohomekit/model/__init__.py", line 281, in process_changes
    accessory = self.aid(aid)
  File "/usr/local/lib/python3.8/site-packages/aiohomekit/model/__init__.py", line 277, in aid
    return next(filter(lambda accessory: accessory.aid == aid, self.accessories))
StopIteration

The above exception was the direct cause of the following exception:

RuntimeError: coroutine raised StopIteration
2020-11-20 18:08:02 ERROR (SyncWorker_35) [homeassistant.components.yeelight] Unable to update device 192.168.1.5, yeelight_ceiling1_0x0000000007c51949: Bulb closed the connection.
2020-11-20 18:08:34 ERROR (MainThread) [homeassistant] Error doing job: Task exception was never retrieved
Traceback (most recent call last):
  File "/usr/src/homeassistant/homeassistant/components/homekit_controller/connection.py", line 376, in async_update
    self.process_new_events(new_values_dict)
  File "/usr/src/homeassistant/homeassistant/components/homekit_controller/connection.py", line 393, in process_new_events
    self.entity_map.process_changes(new_values_dict)
  File "/usr/local/lib/python3.8/site-packages/aiohomekit/model/__init__.py", line 281, in process_changes
    accessory = self.aid(aid)
  File "/usr/local/lib/python3.8/site-packages/aiohomekit/model/__init__.py", line 277, in aid
    return next(filter(lambda accessory: accessory.aid == aid, self.accessories))
StopIteration

The above exception was the direct cause of the following exception:

RuntimeError: coroutine raised StopIteration
2020-11-20 18:09:34 ERROR (MainThread) [homeassistant] Error doing job: Task exception was never retrieved
Traceback (most recent call last):
  File "/usr/src/homeassistant/homeassistant/components/homekit_controller/connection.py", line 376, in async_update
    self.process_new_events(new_values_dict)
  File "/usr/src/homeassistant/homeassistant/components/homekit_controller/connection.py", line 393, in process_new_events
    self.entity_map.process_changes(new_values_dict)
  File "/usr/local/lib/python3.8/site-packages/aiohomekit/model/__init__.py", line 281, in process_changes
    accessory = self.aid(aid)
  File "/usr/local/lib/python3.8/site-packages/aiohomekit/model/__init__.py", line 277, in aid
    return next(filter(lambda accessory: accessory.aid == aid, self.accessories))
StopIteration

The above exception was the direct cause of the following exception:

RuntimeError: coroutine raised StopIteration
2020-11-20 18:10:34 ERROR (MainThread) [homeassistant] Error doing job: Task exception was never retrieved
Traceback (most recent call last):
  File "/usr/src/homeassistant/homeassistant/components/homekit_controller/connection.py", line 376, in async_update
    self.process_new_events(new_values_dict)
  File "/usr/src/homeassistant/homeassistant/components/homekit_controller/connection.py", line 393, in process_new_events
    self.entity_map.process_changes(new_values_dict)
  File "/usr/local/lib/python3.8/site-packages/aiohomekit/model/__init__.py", line 281, in process_changes
    accessory = self.aid(aid)
  File "/usr/local/lib/python3.8/site-packages/aiohomekit/model/__init__.py", line 277, in aid
    return next(filter(lambda accessory: accessory.aid == aid, self.accessories))
StopIteration

The above exception was the direct cause of the following exception:

RuntimeError: coroutine raised StopIteration
2020-11-20 18:11:34 ERROR (MainThread) [homeassistant] Error doing job: Task exception was never retrieved
Traceback (most recent call last):
  File "/usr/src/homeassistant/homeassistant/components/homekit_controller/connection.py", line 376, in async_update
    self.process_new_events(new_values_dict)
  File "/usr/src/homeassistant/homeassistant/components/homekit_controller/connection.py", line 393, in process_new_events
    self.entity_map.process_changes(new_values_dict)
  File "/usr/local/lib/python3.8/site-packages/aiohomekit/model/__init__.py", line 281, in process_changes
    accessory = self.aid(aid)
  File "/usr/local/lib/python3.8/site-packages/aiohomekit/model/__init__.py", line 277, in aid
    return next(filter(lambda accessory: accessory.aid == aid, self.accessories))
StopIteration

The above exception was the direct cause of the following exception:

RuntimeError: coroutine raised StopIteration
2020-11-20 18:12:34 ERROR (MainThread) [homeassistant] Error doing job: Task exception was never retrieved
Traceback (most recent call last):
  File "/usr/src/homeassistant/homeassistant/components/homekit_controller/connection.py", line 376, in async_update
    self.process_new_events(new_values_dict)
  File "/usr/src/homeassistant/homeassistant/components/homekit_controller/connection.py", line 393, in process_new_events
    self.entity_map.process_changes(new_values_dict)
  File "/usr/local/lib/python3.8/site-packages/aiohomekit/model/__init__.py", line 281, in process_changes
    accessory = self.aid(aid)
  File "/usr/local/lib/python3.8/site-packages/aiohomekit/model/__init__.py", line 277, in aid
    return next(filter(lambda accessory: accessory.aid == aid, self.accessories))
StopIteration

The above exception was the direct cause of the following exception:

RuntimeError: coroutine raised StopIteration
2020-11-20 18:12:39 ERROR (MainThread) [homeassistant.util.logging] Exception in async_write_ha_state when dispatching 'homekit_controller_30:D3:1B:A5:C8:D7_state_updated': ()
Traceback (most recent call last):
  File "/usr/src/homeassistant/homeassistant/helpers/entity.py", line 296, in async_write_ha_state
    self._async_write_ha_state()
  File "/usr/src/homeassistant/homeassistant/helpers/entity.py", line 320, in _async_write_ha_state
    sstate = self.state
  File "/usr/src/homeassistant/homeassistant/components/binary_sensor/__init__.py", line 158, in state
    return STATE_ON if self.is_on else STATE_OFF
  File "/usr/src/homeassistant/homeassistant/components/homekit_controller/binary_sensor.py", line 33, in is_on
    return self.service.value(CharacteristicsTypes.MOTION_DETECTED)
  File "/usr/src/homeassistant/homeassistant/components/homekit_controller/__init__.py", line 56, in service
    return self.accessory.services.iid(self._iid)
  File "/usr/src/homeassistant/homeassistant/components/homekit_controller/__init__.py", line 44, in accessory
    return self._accessory.entity_map.aid(self._aid)
  File "/usr/local/lib/python3.8/site-packages/aiohomekit/model/__init__.py", line 277, in aid
    return next(filter(lambda accessory: accessory.aid == aid, self.accessories))
StopIteration

2020-11-20 18:13:05 ERROR (MainThread) [homeassistant.util.logging] Exception in async_write_ha_state when dispatching 'homekit_controller_30:D3:1B:A5:C8:D7_state_updated': ()
Traceback (most recent call last):
  File "/usr/src/homeassistant/homeassistant/helpers/entity.py", line 296, in async_write_ha_state
    self._async_write_ha_state()
  File "/usr/src/homeassistant/homeassistant/helpers/entity.py", line 320, in _async_write_ha_state
    sstate = self.state
  File "/usr/src/homeassistant/homeassistant/components/binary_sensor/__init__.py", line 158, in state
    return STATE_ON if self.is_on else STATE_OFF
  File "/usr/src/homeassistant/homeassistant/components/homekit_controller/binary_sensor.py", line 33, in is_on
    return self.service.value(CharacteristicsTypes.MOTION_DETECTED)
  File "/usr/src/homeassistant/homeassistant/components/homekit_controller/__init__.py", line 56, in service
    return self.accessory.services.iid(self._iid)
  File "/usr/src/homeassistant/homeassistant/components/homekit_controller/__init__.py", line 44, in accessory
    return self._accessory.entity_map.aid(self._aid)
  File "/usr/local/lib/python3.8/site-packages/aiohomekit/model/__init__.py", line 277, in aid
    return next(filter(lambda accessory: accessory.aid == aid, self.accessories))
StopIteration

2020-11-20 18:13:08 ERROR (MainThread) [homeassistant.util.logging] Exception in async_write_ha_state when dispatching 'homekit_controller_30:D3:1B:A5:C8:D7_state_updated': ()
Traceback (most recent call last):
  File "/usr/src/homeassistant/homeassistant/helpers/entity.py", line 296, in async_write_ha_state
    self._async_write_ha_state()
  File "/usr/src/homeassistant/homeassistant/helpers/entity.py", line 320, in _async_write_ha_state
    sstate = self.state
  File "/usr/src/homeassistant/homeassistant/components/binary_sensor/__init__.py", line 158, in state
    return STATE_ON if self.is_on else STATE_OFF
  File "/usr/src/homeassistant/homeassistant/components/homekit_controller/binary_sensor.py", line 33, in is_on
    return self.service.value(CharacteristicsTypes.MOTION_DETECTED)
  File "/usr/src/homeassistant/homeassistant/components/homekit_controller/__init__.py", line 56, in service
    return self.accessory.services.iid(self._iid)
  File "/usr/src/homeassistant/homeassistant/components/homekit_controller/__init__.py", line 44, in accessory
    return self._accessory.entity_map.aid(self._aid)
  File "/usr/local/lib/python3.8/site-packages/aiohomekit/model/__init__.py", line 277, in aid
    return next(filter(lambda accessory: accessory.aid == aid, self.accessories))
StopIteration

2020-11-20 18:13:09 ERROR (MainThread) [homeassistant.util.logging] Exception in async_write_ha_state when dispatching 'homekit_controller_30:D3:1B:A5:C8:D7_state_updated': ()
Traceback (most recent call last):
  File "/usr/src/homeassistant/homeassistant/helpers/entity.py", line 296, in async_write_ha_state
    self._async_write_ha_state()
  File "/usr/src/homeassistant/homeassistant/helpers/entity.py", line 320, in _async_write_ha_state
    sstate = self.state
  File "/usr/src/homeassistant/homeassistant/components/binary_sensor/__init__.py", line 158, in state
    return STATE_ON if self.is_on else STATE_OFF
  File "/usr/src/homeassistant/homeassistant/components/homekit_controller/binary_sensor.py", line 33, in is_on
    return self.service.value(CharacteristicsTypes.MOTION_DETECTED)
  File "/usr/src/homeassistant/homeassistant/components/homekit_controller/__init__.py", line 56, in service
    return self.accessory.services.iid(self._iid)
  File "/usr/src/homeassistant/homeassistant/components/homekit_controller/__init__.py", line 44, in accessory
    return self._accessory.entity_map.aid(self._aid)
  File "/usr/local/lib/python3.8/site-packages/aiohomekit/model/__init__.py", line 277, in aid
    return next(filter(lambda accessory: accessory.aid == aid, self.accessories))
StopIteration

2020-11-20 18:13:09 ERROR (MainThread) [homeassistant.util.logging] Exception in async_write_ha_state when dispatching 'homekit_controller_30:D3:1B:A5:C8:D7_state_updated': ()
Traceback (most recent call last):
  File "/usr/src/homeassistant/homeassistant/helpers/entity.py", line 296, in async_write_ha_state
    self._async_write_ha_state()
  File "/usr/src/homeassistant/homeassistant/helpers/entity.py", line 320, in _async_write_ha_state
    sstate = self.state
  File "/usr/src/homeassistant/homeassistant/components/binary_sensor/__init__.py", line 158, in state
    return STATE_ON if self.is_on else STATE_OFF
  File "/usr/src/homeassistant/homeassistant/components/homekit_controller/binary_sensor.py", line 33, in is_on
    return self.service.value(CharacteristicsTypes.MOTION_DETECTED)
  File "/usr/src/homeassistant/homeassistant/components/homekit_controller/__init__.py", line 56, in service
    return self.accessory.services.iid(self._iid)
  File "/usr/src/homeassistant/homeassistant/components/homekit_controller/__init__.py", line 44, in accessory
    return self._accessory.entity_map.aid(self._aid)
  File "/usr/local/lib/python3.8/site-packages/aiohomekit/model/__init__.py", line 277, in aid
    return next(filter(lambda accessory: accessory.aid == aid, self.accessories))
StopIteration

2020-11-20 18:13:34 ERROR (MainThread) [homeassistant] Error doing job: Task exception was never retrieved
Traceback (most recent call last):
  File "/usr/src/homeassistant/homeassistant/components/homekit_controller/connection.py", line 376, in async_update
    self.process_new_events(new_values_dict)
  File "/usr/src/homeassistant/homeassistant/components/homekit_controller/connection.py", line 393, in process_new_events
    self.entity_map.process_changes(new_values_dict)
  File "/usr/local/lib/python3.8/site-packages/aiohomekit/model/__init__.py", line 281, in process_changes
    accessory = self.aid(aid)
  File "/usr/local/lib/python3.8/site-packages/aiohomekit/model/__init__.py", line 277, in aid
    return next(filter(lambda accessory: accessory.aid == aid, self.accessories))
StopIteration

The above exception was the direct cause of the following exception:

RuntimeError: coroutine raised StopIteration
2020-11-20 18:13:38 ERROR (MainThread) [homeassistant.util.logging] Exception in async_write_ha_state when dispatching 'homekit_controller_30:D3:1B:A5:C8:D7_state_updated': ()
Traceback (most recent call last):
  File "/usr/src/homeassistant/homeassistant/helpers/entity.py", line 296, in async_write_ha_state
    self._async_write_ha_state()
  File "/usr/src/homeassistant/homeassistant/helpers/entity.py", line 320, in _async_write_ha_state
    sstate = self.state
  File "/usr/src/homeassistant/homeassistant/components/binary_sensor/__init__.py", line 158, in state
    return STATE_ON if self.is_on else STATE_OFF
  File "/usr/src/homeassistant/homeassistant/components/homekit_controller/binary_sensor.py", line 33, in is_on
    return self.service.value(CharacteristicsTypes.MOTION_DETECTED)
  File "/usr/src/homeassistant/homeassistant/components/homekit_controller/__init__.py", line 56, in service
    return self.accessory.services.iid(self._iid)
  File "/usr/src/homeassistant/homeassistant/components/homekit_controller/__init__.py", line 44, in accessory
    return self._accessory.entity_map.aid(self._aid)
  File "/usr/local/lib/python3.8/site-packages/aiohomekit/model/__init__.py", line 277, in aid
    return next(filter(lambda accessory: accessory.aid == aid, self.accessories))
StopIteration

2020-11-20 18:14:08 ERROR (MainThread) [homeassistant.util.logging] Exception in async_write_ha_state when dispatching 'homekit_controller_30:D3:1B:A5:C8:D7_state_updated': ()
Traceback (most recent call last):
  File "/usr/src/homeassistant/homeassistant/helpers/entity.py", line 296, in async_write_ha_state
    self._async_write_ha_state()
  File "/usr/src/homeassistant/homeassistant/helpers/entity.py", line 320, in _async_write_ha_state
    sstate = self.state
  File "/usr/src/homeassistant/homeassistant/components/binary_sensor/__init__.py", line 158, in state
    return STATE_ON if self.is_on else STATE_OFF
  File "/usr/src/homeassistant/homeassistant/components/homekit_controller/binary_sensor.py", line 33, in is_on
    return self.service.value(CharacteristicsTypes.MOTION_DETECTED)
  File "/usr/src/homeassistant/homeassistant/components/homekit_controller/__init__.py", line 56, in service
    return self.accessory.services.iid(self._iid)
  File "/usr/src/homeassistant/homeassistant/components/homekit_controller/__init__.py", line 44, in accessory
    return self._accessory.entity_map.aid(self._aid)
  File "/usr/local/lib/python3.8/site-packages/aiohomekit/model/__init__.py", line 277, in aid
    return next(filter(lambda accessory: accessory.aid == aid, self.accessories))
StopIteration

2020-11-20 18:14:14 ERROR (MainThread) [homeassistant.util.logging] Exception in async_write_ha_state when dispatching 'homekit_controller_30:D3:1B:A5:C8:D7_state_updated': ()
Traceback (most recent call last):
  File "/usr/src/homeassistant/homeassistant/helpers/entity.py", line 296, in async_write_ha_state
    self._async_write_ha_state()
  File "/usr/src/homeassistant/homeassistant/helpers/entity.py", line 320, in _async_write_ha_state
    sstate = self.state
  File "/usr/src/homeassistant/homeassistant/components/binary_sensor/__init__.py", line 158, in state
    return STATE_ON if self.is_on else STATE_OFF
  File "/usr/src/homeassistant/homeassistant/components/homekit_controller/binary_sensor.py", line 33, in is_on
    return self.service.value(CharacteristicsTypes.MOTION_DETECTED)
  File "/usr/src/homeassistant/homeassistant/components/homekit_controller/__init__.py", line 56, in service
    return self.accessory.services.iid(self._iid)
  File "/usr/src/homeassistant/homeassistant/components/homekit_controller/__init__.py", line 44, in accessory
    return self._accessory.entity_map.aid(self._aid)
  File "/usr/local/lib/python3.8/site-packages/aiohomekit/model/__init__.py", line 277, in aid
    return next(filter(lambda accessory: accessory.aid == aid, self.accessories))
StopIteration

2020-11-20 18:14:14 ERROR (MainThread) [homeassistant.util.logging] Exception in async_write_ha_state when dispatching 'homekit_controller_30:D3:1B:A5:C8:D7_state_updated': ()
Traceback (most recent call last):
  File "/usr/src/homeassistant/homeassistant/helpers/entity.py", line 296, in async_write_ha_state
    self._async_write_ha_state()
  File "/usr/src/homeassistant/homeassistant/helpers/entity.py", line 320, in _async_write_ha_state
    sstate = self.state
  File "/usr/src/homeassistant/homeassistant/components/binary_sensor/__init__.py", line 158, in state
    return STATE_ON if self.is_on else STATE_OFF
  File "/usr/src/homeassistant/homeassistant/components/homekit_controller/binary_sensor.py", line 33, in is_on
    return self.service.value(CharacteristicsTypes.MOTION_DETECTED)
  File "/usr/src/homeassistant/homeassistant/components/homekit_controller/__init__.py", line 56, in service
    return self.accessory.services.iid(self._iid)
  File "/usr/src/homeassistant/homeassistant/components/homekit_controller/__init__.py", line 44, in accessory
    return self._accessory.entity_map.aid(self._aid)
  File "/usr/local/lib/python3.8/site-packages/aiohomekit/model/__init__.py", line 277, in aid
    return next(filter(lambda accessory: accessory.aid == aid, self.accessories))
StopIteration

2020-11-20 18:14:34 ERROR (MainThread) [homeassistant] Error doing job: Task exception was never retrieved
Traceback (most recent call last):
  File "/usr/src/homeassistant/homeassistant/components/homekit_controller/connection.py", line 376, in async_update
    self.process_new_events(new_values_dict)
  File "/usr/src/homeassistant/homeassistant/components/homekit_controller/connection.py", line 393, in process_new_events
    self.entity_map.process_changes(new_values_dict)
  File "/usr/local/lib/python3.8/site-packages/aiohomekit/model/__init__.py", line 281, in process_changes
    accessory = self.aid(aid)
  File "/usr/local/lib/python3.8/site-packages/aiohomekit/model/__init__.py", line 277, in aid
    return next(filter(lambda accessory: accessory.aid == aid, self.accessories))
StopIteration

The above exception was the direct cause of the following exception:

RuntimeError: coroutine raised StopIteration
2020-11-20 18:15:34 ERROR (MainThread) [homeassistant] Error doing job: Task exception was never retrieved
Traceback (most recent call last):
  File "/usr/src/homeassistant/homeassistant/components/homekit_controller/connection.py", line 376, in async_update
    self.process_new_events(new_values_dict)
  File "/usr/src/homeassistant/homeassistant/components/homekit_controller/connection.py", line 393, in process_new_events
    self.entity_map.process_changes(new_values_dict)
  File "/usr/local/lib/python3.8/site-packages/aiohomekit/model/__init__.py", line 281, in process_changes
    accessory = self.aid(aid)
  File "/usr/local/lib/python3.8/site-packages/aiohomekit/model/__init__.py", line 277, in aid
    return next(filter(lambda accessory: accessory.aid == aid, self.accessories))
StopIteration

The above exception was the direct cause of the following exception:

RuntimeError: coroutine raised StopIteration
2020-11-20 18:16:34 ERROR (MainThread) [homeassistant] Error doing job: Task exception was never retrieved
Traceback (most recent call last):
  File "/usr/src/homeassistant/homeassistant/components/homekit_controller/connection.py", line 376, in async_update
    self.process_new_events(new_values_dict)
  File "/usr/src/homeassistant/homeassistant/components/homekit_controller/connection.py", line 393, in process_new_events
    self.entity_map.process_changes(new_values_dict)
  File "/usr/local/lib/python3.8/site-packages/aiohomekit/model/__init__.py", line 281, in process_changes
    accessory = self.aid(aid)
  File "/usr/local/lib/python3.8/site-packages/aiohomekit/model/__init__.py", line 277, in aid
    return next(filter(lambda accessory: accessory.aid == aid, self.accessories))
StopIteration

The above exception was the direct cause of the following exception:

RuntimeError: coroutine raised StopIteration
2020-11-20 18:17:34 ERROR (MainThread) [homeassistant] Error doing job: Task exception was never retrieved
Traceback (most recent call last):
  File "/usr/src/homeassistant/homeassistant/components/homekit_controller/connection.py", line 376, in async_update
    self.process_new_events(new_values_dict)
  File "/usr/src/homeassistant/homeassistant/components/homekit_controller/connection.py", line 393, in process_new_events
    self.entity_map.process_changes(new_values_dict)
  File "/usr/local/lib/python3.8/site-packages/aiohomekit/model/__init__.py", line 281, in process_changes
    accessory = self.aid(aid)
  File "/usr/local/lib/python3.8/site-packages/aiohomekit/model/__init__.py", line 277, in aid
    return next(filter(lambda accessory: accessory.aid == aid, self.accessories))
StopIteration

The above exception was the direct cause of the following exception:

RuntimeError: coroutine raised StopIteration
2020-11-20 18:18:34 ERROR (MainThread) [homeassistant] Error doing job: Task exception was never retrieved
Traceback (most recent call last):
  File "/usr/src/homeassistant/homeassistant/components/homekit_controller/connection.py", line 376, in async_update
    self.process_new_events(new_values_dict)
  File "/usr/src/homeassistant/homeassistant/components/homekit_controller/connection.py", line 393, in process_new_events
    self.entity_map.process_changes(new_values_dict)
  File "/usr/local/lib/python3.8/site-packages/aiohomekit/model/__init__.py", line 281, in process_changes
    accessory = self.aid(aid)
  File "/usr/local/lib/python3.8/site-packages/aiohomekit/model/__init__.py", line 277, in aid
    return next(filter(lambda accessory: accessory.aid == aid, self.accessories))
StopIteration

The above exception was the direct cause of the following exception:

RuntimeError: coroutine raised StopIteration
2020-11-20 18:19:34 ERROR (MainThread) [homeassistant] Error doing job: Task exception was never retrieved
Traceback (most recent call last):
  File "/usr/src/homeassistant/homeassistant/components/homekit_controller/connection.py", line 376, in async_update
    self.process_new_events(new_values_dict)
  File "/usr/src/homeassistant/homeassistant/components/homekit_controller/connection.py", line 393, in process_new_events
    self.entity_map.process_changes(new_values_dict)
  File "/usr/local/lib/python3.8/site-packages/aiohomekit/model/__init__.py", line 281, in process_changes
    accessory = self.aid(aid)
  File "/usr/local/lib/python3.8/site-packages/aiohomekit/model/__init__.py", line 277, in aid
    return next(filter(lambda accessory: accessory.aid == aid, self.accessories))
StopIteration

The above exception was the direct cause of the following exception:

RuntimeError: coroutine raised StopIteration
2020-11-20 18:20:34 ERROR (MainThread) [homeassistant] Error doing job: Task exception was never retrieved
Traceback (most recent call last):
  File "/usr/src/homeassistant/homeassistant/components/homekit_controller/connection.py", line 376, in async_update
    self.process_new_events(new_values_dict)
  File "/usr/src/homeassistant/homeassistant/components/homekit_controller/connection.py", line 393, in process_new_events
    self.entity_map.process_changes(new_values_dict)
  File "/usr/local/lib/python3.8/site-packages/aiohomekit/model/__init__.py", line 281, in process_changes
    accessory = self.aid(aid)
  File "/usr/local/lib/python3.8/site-packages/aiohomekit/model/__init__.py", line 277, in aid
    return next(filter(lambda accessory: accessory.aid == aid, self.accessories))
StopIteration

The above exception was the direct cause of the following exception:

RuntimeError: coroutine raised StopIteration
2020-11-20 18:21:34 ERROR (MainThread) [homeassistant] Error doing job: Task exception was never retrieved
Traceback (most recent call last):
  File "/usr/src/homeassistant/homeassistant/components/homekit_controller/connection.py", line 376, in async_update
    self.process_new_events(new_values_dict)
  File "/usr/src/homeassistant/homeassistant/components/homekit_controller/connection.py", line 393, in process_new_events
    self.entity_map.process_changes(new_values_dict)
  File "/usr/local/lib/python3.8/site-packages/aiohomekit/model/__init__.py", line 281, in process_changes
    accessory = self.aid(aid)
  File "/usr/local/lib/python3.8/site-packages/aiohomekit/model/__init__.py", line 277, in aid
    return next(filter(lambda accessory: accessory.aid == aid, self.accessories))
StopIteration

The above exception was the direct cause of the following exception:

RuntimeError: coroutine raised StopIteration
2020-11-20 18:22:34 ERROR (MainThread) [homeassistant] Error doing job: Task exception was never retrieved
Traceback (most recent call last):
  File "/usr/src/homeassistant/homeassistant/components/homekit_controller/connection.py", line 376, in async_update
    self.process_new_events(new_values_dict)
  File "/usr/src/homeassistant/homeassistant/components/homekit_controller/connection.py", line 393, in process_new_events
    self.entity_map.process_changes(new_values_dict)
  File "/usr/local/lib/python3.8/site-packages/aiohomekit/model/__init__.py", line 281, in process_changes
    accessory = self.aid(aid)
  File "/usr/local/lib/python3.8/site-packages/aiohomekit/model/__init__.py", line 277, in aid
    return next(filter(lambda accessory: accessory.aid == aid, self.accessories))
StopIteration

The above exception was the direct cause of the following exception:

RuntimeError: coroutine raised StopIteration
2020-11-20 18:23:34 ERROR (MainThread) [homeassistant] Error doing job: Task exception was never retrieved
Traceback (most recent call last):
  File "/usr/src/homeassistant/homeassistant/components/homekit_controller/connection.py", line 376, in async_update
    self.process_new_events(new_values_dict)
  File "/usr/src/homeassistant/homeassistant/components/homekit_controller/connection.py", line 393, in process_new_events
    self.entity_map.process_changes(new_values_dict)
  File "/usr/local/lib/python3.8/site-packages/aiohomekit/model/__init__.py", line 281, in process_changes
    accessory = self.aid(aid)
  File "/usr/local/lib/python3.8/site-packages/aiohomekit/model/__init__.py", line 277, in aid
    return next(filter(lambda accessory: accessory.aid == aid, self.accessories))
StopIteration

The above exception was the direct cause of the following exception:

RuntimeError: coroutine raised StopIteration
2020-11-20 18:24:28 ERROR (MainThread) [homeassistant.util.logging] Exception in async_write_ha_state when dispatching 'homekit_controller_30:D3:1B:A5:C8:D7_state_updated': ()
Traceback (most recent call last):
  File "/usr/src/homeassistant/homeassistant/helpers/entity.py", line 296, in async_write_ha_state
    self._async_write_ha_state()
  File "/usr/src/homeassistant/homeassistant/helpers/entity.py", line 320, in _async_write_ha_state
    sstate = self.state
  File "/usr/src/homeassistant/homeassistant/components/binary_sensor/__init__.py", line 158, in state
    return STATE_ON if self.is_on else STATE_OFF
  File "/usr/src/homeassistant/homeassistant/components/homekit_controller/binary_sensor.py", line 33, in is_on
    return self.service.value(CharacteristicsTypes.MOTION_DETECTED)
  File "/usr/src/homeassistant/homeassistant/components/homekit_controller/__init__.py", line 56, in service
    return self.accessory.services.iid(self._iid)
  File "/usr/src/homeassistant/homeassistant/components/homekit_controller/__init__.py", line 44, in accessory
    return self._accessory.entity_map.aid(self._aid)
  File "/usr/local/lib/python3.8/site-packages/aiohomekit/model/__init__.py", line 277, in aid
    return next(filter(lambda accessory: accessory.aid == aid, self.accessories))
StopIteration

2020-11-20 18:24:28 ERROR (MainThread) [homeassistant.util.logging] Exception in async_write_ha_state when dispatching 'homekit_controller_30:D3:1B:A5:C8:D7_state_updated': ()
Traceback (most recent call last):
  File "/usr/src/homeassistant/homeassistant/helpers/entity.py", line 296, in async_write_ha_state
    self._async_write_ha_state()
  File "/usr/src/homeassistant/homeassistant/helpers/entity.py", line 320, in _async_write_ha_state
    sstate = self.state
  File "/usr/src/homeassistant/homeassistant/components/binary_sensor/__init__.py", line 158, in state
    return STATE_ON if self.is_on else STATE_OFF
  File "/usr/src/homeassistant/homeassistant/components/homekit_controller/binary_sensor.py", line 33, in is_on
    return self.service.value(CharacteristicsTypes.MOTION_DETECTED)
  File "/usr/src/homeassistant/homeassistant/components/homekit_controller/__init__.py", line 56, in service
    return self.accessory.services.iid(self._iid)
  File "/usr/src/homeassistant/homeassistant/components/homekit_controller/__init__.py", line 44, in accessory
    return self._accessory.entity_map.aid(self._aid)
  File "/usr/local/lib/python3.8/site-packages/aiohomekit/model/__init__.py", line 277, in aid
    return next(filter(lambda accessory: accessory.aid == aid, self.accessories))
StopIteration

2020-11-20 18:24:29 ERROR (MainThread) [homeassistant.util.logging] Exception in async_write_ha_state when dispatching 'homekit_controller_30:D3:1B:A5:C8:D7_state_updated': ()
Traceback (most recent call last):
  File "/usr/src/homeassistant/homeassistant/helpers/entity.py", line 296, in async_write_ha_state
    self._async_write_ha_state()
  File "/usr/src/homeassistant/homeassistant/helpers/entity.py", line 320, in _async_write_ha_state
    sstate = self.state
  File "/usr/src/homeassistant/homeassistant/components/binary_sensor/__init__.py", line 158, in state
    return STATE_ON if self.is_on else STATE_OFF
  File "/usr/src/homeassistant/homeassistant/components/homekit_controller/binary_sensor.py", line 33, in is_on
    return self.service.value(CharacteristicsTypes.MOTION_DETECTED)
  File "/usr/src/homeassistant/homeassistant/components/homekit_controller/__init__.py", line 56, in service
    return self.accessory.services.iid(self._iid)
  File "/usr/src/homeassistant/homeassistant/components/homekit_controller/__init__.py", line 44, in accessory
    return self._accessory.entity_map.aid(self._aid)
  File "/usr/local/lib/python3.8/site-packages/aiohomekit/model/__init__.py", line 277, in aid
    return next(filter(lambda accessory: accessory.aid == aid, self.accessories))
StopIteration

2020-11-20 18:24:29 ERROR (MainThread) [homeassistant.util.logging] Exception in async_write_ha_state when dispatching 'homekit_controller_30:D3:1B:A5:C8:D7_state_updated': ()
Traceback (most recent call last):
  File "/usr/src/homeassistant/homeassistant/helpers/entity.py", line 296, in async_write_ha_state
    self._async_write_ha_state()
  File "/usr/src/homeassistant/homeassistant/helpers/entity.py", line 320, in _async_write_ha_state
    sstate = self.state
  File "/usr/src/homeassistant/homeassistant/components/binary_sensor/__init__.py", line 158, in state
    return STATE_ON if self.is_on else STATE_OFF
  File "/usr/src/homeassistant/homeassistant/components/homekit_controller/binary_sensor.py", line 33, in is_on
    return self.service.value(CharacteristicsTypes.MOTION_DETECTED)
  File "/usr/src/homeassistant/homeassistant/components/homekit_controller/__init__.py", line 56, in service
    return self.accessory.services.iid(self._iid)
  File "/usr/src/homeassistant/homeassistant/components/homekit_controller/__init__.py", line 44, in accessory
    return self._accessory.entity_map.aid(self._aid)
  File "/usr/local/lib/python3.8/site-packages/aiohomekit/model/__init__.py", line 277, in aid
    return next(filter(lambda accessory: accessory.aid == aid, self.accessories))
StopIteration

2020-11-20 18:24:30 ERROR (MainThread) [homeassistant.util.logging] Exception in async_write_ha_state when dispatching 'homekit_controller_30:D3:1B:A5:C8:D7_state_updated': ()
Traceback (most recent call last):
  File "/usr/src/homeassistant/homeassistant/helpers/entity.py", line 296, in async_write_ha_state
    self._async_write_ha_state()
  File "/usr/src/homeassistant/homeassistant/helpers/entity.py", line 320, in _async_write_ha_state
    sstate = self.state
  File "/usr/src/homeassistant/homeassistant/components/binary_sensor/__init__.py", line 158, in state
    return STATE_ON if self.is_on else STATE_OFF
  File "/usr/src/homeassistant/homeassistant/components/homekit_controller/binary_sensor.py", line 33, in is_on
    return self.service.value(CharacteristicsTypes.MOTION_DETECTED)
  File "/usr/src/homeassistant/homeassistant/components/homekit_controller/__init__.py", line 56, in service
    return self.accessory.services.iid(self._iid)
  File "/usr/src/homeassistant/homeassistant/components/homekit_controller/__init__.py", line 44, in accessory
    return self._accessory.entity_map.aid(self._aid)
  File "/usr/local/lib/python3.8/site-packages/aiohomekit/model/__init__.py", line 277, in aid
    return next(filter(lambda accessory: accessory.aid == aid, self.accessories))
StopIteration

2020-11-20 18:24:30 ERROR (MainThread) [homeassistant.util.logging] Exception in async_write_ha_state when dispatching 'homekit_controller_30:D3:1B:A5:C8:D7_state_updated': ()
Traceback (most recent call last):
  File "/usr/src/homeassistant/homeassistant/helpers/entity.py", line 296, in async_write_ha_state
    self._async_write_ha_state()
  File "/usr/src/homeassistant/homeassistant/helpers/entity.py", line 320, in _async_write_ha_state
    sstate = self.state
  File "/usr/src/homeassistant/homeassistant/components/binary_sensor/__init__.py", line 158, in state
    return STATE_ON if self.is_on else STATE_OFF
  File "/usr/src/homeassistant/homeassistant/components/homekit_controller/binary_sensor.py", line 33, in is_on
    return self.service.value(CharacteristicsTypes.MOTION_DETECTED)
  File "/usr/src/homeassistant/homeassistant/components/homekit_controller/__init__.py", line 56, in service
    return self.accessory.services.iid(self._iid)
  File "/usr/src/homeassistant/homeassistant/components/homekit_controller/__init__.py", line 44, in accessory
    return self._accessory.entity_map.aid(self._aid)
  File "/usr/local/lib/python3.8/site-packages/aiohomekit/model/__init__.py", line 277, in aid
    return next(filter(lambda accessory: accessory.aid == aid, self.accessories))
StopIteration

2020-11-20 18:24:34 ERROR (MainThread) [homeassistant] Error doing job: Task exception was never retrieved
Traceback (most recent call last):
  File "/usr/src/homeassistant/homeassistant/components/homekit_controller/connection.py", line 376, in async_update
    self.process_new_events(new_values_dict)
  File "/usr/src/homeassistant/homeassistant/components/homekit_controller/connection.py", line 393, in process_new_events
    self.entity_map.process_changes(new_values_dict)
  File "/usr/local/lib/python3.8/site-packages/aiohomekit/model/__init__.py", line 281, in process_changes
    accessory = self.aid(aid)
  File "/usr/local/lib/python3.8/site-packages/aiohomekit/model/__init__.py", line 277, in aid
    return next(filter(lambda accessory: accessory.aid == aid, self.accessories))
StopIteration

The above exception was the direct cause of the following exception:

RuntimeError: coroutine raised StopIteration
2020-11-20 18:24:58 ERROR (MainThread) [homeassistant.util.logging] Exception in async_write_ha_state when dispatching 'homekit_controller_30:D3:1B:A5:C8:D7_state_updated': ()
Traceback (most recent call last):
  File "/usr/src/homeassistant/homeassistant/helpers/entity.py", line 296, in async_write_ha_state
    self._async_write_ha_state()
  File "/usr/src/homeassistant/homeassistant/helpers/entity.py", line 320, in _async_write_ha_state
    sstate = self.state
  File "/usr/src/homeassistant/homeassistant/components/binary_sensor/__init__.py", line 158, in state
    return STATE_ON if self.is_on else STATE_OFF
  File "/usr/src/homeassistant/homeassistant/components/homekit_controller/binary_sensor.py", line 33, in is_on
    return self.service.value(CharacteristicsTypes.MOTION_DETECTED)
  File "/usr/src/homeassistant/homeassistant/components/homekit_controller/__init__.py", line 56, in service
    return self.accessory.services.iid(self._iid)
  File "/usr/src/homeassistant/homeassistant/components/homekit_controller/__init__.py", line 44, in accessory
    return self._accessory.entity_map.aid(self._aid)
  File "/usr/local/lib/python3.8/site-packages/aiohomekit/model/__init__.py", line 277, in aid
    return next(filter(lambda accessory: accessory.aid == aid, self.accessories))
StopIteration

2020-11-20 18:24:58 ERROR (MainThread) [homeassistant.util.logging] Exception in async_write_ha_state when dispatching 'homekit_controller_30:D3:1B:A5:C8:D7_state_updated': ()
Traceback (most recent call last):
  File "/usr/src/homeassistant/homeassistant/helpers/entity.py", line 296, in async_write_ha_state
    self._async_write_ha_state()
  File "/usr/src/homeassistant/homeassistant/helpers/entity.py", line 320, in _async_write_ha_state
    sstate = self.state
  File "/usr/src/homeassistant/homeassistant/components/binary_sensor/__init__.py", line 158, in state
    return STATE_ON if self.is_on else STATE_OFF
  File "/usr/src/homeassistant/homeassistant/components/homekit_controller/binary_sensor.py", line 33, in is_on
    return self.service.value(CharacteristicsTypes.MOTION_DETECTED)
  File "/usr/src/homeassistant/homeassistant/components/homekit_controller/__init__.py", line 56, in service
    return self.accessory.services.iid(self._iid)
  File "/usr/src/homeassistant/homeassistant/components/homekit_controller/__init__.py", line 44, in accessory
    return self._accessory.entity_map.aid(self._aid)
  File "/usr/local/lib/python3.8/site-packages/aiohomekit/model/__init__.py", line 277, in aid
    return next(filter(lambda accessory: accessory.aid == aid, self.accessories))
StopIteration

2020-11-20 18:25:29 ERROR (MainThread) [homeassistant.util.logging] Exception in async_write_ha_state when dispatching 'homekit_controller_30:D3:1B:A5:C8:D7_state_updated': ()
Traceback (most recent call last):
  File "/usr/src/homeassistant/homeassistant/helpers/entity.py", line 296, in async_write_ha_state
    self._async_write_ha_state()
  File "/usr/src/homeassistant/homeassistant/helpers/entity.py", line 320, in _async_write_ha_state
    sstate = self.state
  File "/usr/src/homeassistant/homeassistant/components/binary_sensor/__init__.py", line 158, in state
    return STATE_ON if self.is_on else STATE_OFF
  File "/usr/src/homeassistant/homeassistant/components/homekit_controller/binary_sensor.py", line 33, in is_on
    return self.service.value(CharacteristicsTypes.MOTION_DETECTED)
  File "/usr/src/homeassistant/homeassistant/components/homekit_controller/__init__.py", line 56, in service
    return self.accessory.services.iid(self._iid)
  File "/usr/src/homeassistant/homeassistant/components/homekit_controller/__init__.py", line 44, in accessory
    return self._accessory.entity_map.aid(self._aid)
  File "/usr/local/lib/python3.8/site-packages/aiohomekit/model/__init__.py", line 277, in aid
    return next(filter(lambda accessory: accessory.aid == aid, self.accessories))
StopIteration

2020-11-20 18:25:30 ERROR (MainThread) [homeassistant.util.logging] Exception in async_write_ha_state when dispatching 'homekit_controller_30:D3:1B:A5:C8:D7_state_updated': ()
Traceback (most recent call last):
  File "/usr/src/homeassistant/homeassistant/helpers/entity.py", line 296, in async_write_ha_state
    self._async_write_ha_state()
  File "/usr/src/homeassistant/homeassistant/helpers/entity.py", line 320, in _async_write_ha_state
    sstate = self.state
  File "/usr/src/homeassistant/homeassistant/components/binary_sensor/__init__.py", line 158, in state
    return STATE_ON if self.is_on else STATE_OFF
  File "/usr/src/homeassistant/homeassistant/components/homekit_controller/binary_sensor.py", line 33, in is_on
    return self.service.value(CharacteristicsTypes.MOTION_DETECTED)
  File "/usr/src/homeassistant/homeassistant/components/homekit_controller/__init__.py", line 56, in service
    return self.accessory.services.iid(self._iid)
  File "/usr/src/homeassistant/homeassistant/components/homekit_controller/__init__.py", line 44, in accessory
    return self._accessory.entity_map.aid(self._aid)
  File "/usr/local/lib/python3.8/site-packages/aiohomekit/model/__init__.py", line 277, in aid
    return next(filter(lambda accessory: accessory.aid == aid, self.accessories))
StopIteration

2020-11-20 18:25:34 ERROR (MainThread) [homeassistant] Error doing job: Task exception was never retrieved
Traceback (most recent call last):
  File "/usr/src/homeassistant/homeassistant/components/homekit_controller/connection.py", line 376, in async_update
    self.process_new_events(new_values_dict)
  File "/usr/src/homeassistant/homeassistant/components/homekit_controller/connection.py", line 393, in process_new_events
    self.entity_map.process_changes(new_values_dict)
  File "/usr/local/lib/python3.8/site-packages/aiohomekit/model/__init__.py", line 281, in process_changes
    accessory = self.aid(aid)
  File "/usr/local/lib/python3.8/site-packages/aiohomekit/model/__init__.py", line 277, in aid
    return next(filter(lambda accessory: accessory.aid == aid, self.accessories))
StopIteration

The above exception was the direct cause of the following exception:

RuntimeError: coroutine raised StopIteration
2020-11-20 18:25:35 ERROR (MainThread) [homeassistant.util.logging] Exception in async_write_ha_state when dispatching 'homekit_controller_30:D3:1B:A5:C8:D7_state_updated': ()
Traceback (most recent call last):
  File "/usr/src/homeassistant/homeassistant/helpers/entity.py", line 296, in async_write_ha_state
    self._async_write_ha_state()
  File "/usr/src/homeassistant/homeassistant/helpers/entity.py", line 320, in _async_write_ha_state
    sstate = self.state
  File "/usr/src/homeassistant/homeassistant/components/binary_sensor/__init__.py", line 158, in state
    return STATE_ON if self.is_on else STATE_OFF
  File "/usr/src/homeassistant/homeassistant/components/homekit_controller/binary_sensor.py", line 33, in is_on
    return self.service.value(CharacteristicsTypes.MOTION_DETECTED)
  File "/usr/src/homeassistant/homeassistant/components/homekit_controller/__init__.py", line 56, in service
    return self.accessory.services.iid(self._iid)
  File "/usr/src/homeassistant/homeassistant/components/homekit_controller/__init__.py", line 44, in accessory
    return self._accessory.entity_map.aid(self._aid)
  File "/usr/local/lib/python3.8/site-packages/aiohomekit/model/__init__.py", line 277, in aid
    return next(filter(lambda accessory: accessory.aid == aid, self.accessories))
StopIteration

2020-11-20 18:25:35 ERROR (MainThread) [homeassistant.util.logging] Exception in async_write_ha_state when dispatching 'homekit_controller_30:D3:1B:A5:C8:D7_state_updated': ()
Traceback (most recent call last):
  File "/usr/src/homeassistant/homeassistant/helpers/entity.py", line 296, in async_write_ha_state
    self._async_write_ha_state()
  File "/usr/src/homeassistant/homeassistant/helpers/entity.py", line 320, in _async_write_ha_state
    sstate = self.state
  File "/usr/src/homeassistant/homeassistant/components/binary_sensor/__init__.py", line 158, in state
    return STATE_ON if self.is_on else STATE_OFF
  File "/usr/src/homeassistant/homeassistant/components/homekit_controller/binary_sensor.py", line 33, in is_on
    return self.service.value(CharacteristicsTypes.MOTION_DETECTED)
  File "/usr/src/homeassistant/homeassistant/components/homekit_controller/__init__.py", line 56, in service
    return self.accessory.services.iid(self._iid)
  File "/usr/src/homeassistant/homeassistant/components/homekit_controller/__init__.py", line 44, in accessory
    return self._accessory.entity_map.aid(self._aid)
  File "/usr/local/lib/python3.8/site-packages/aiohomekit/model/__init__.py", line 277, in aid
    return next(filter(lambda accessory: accessory.aid == aid, self.accessories))
StopIteration

2020-11-20 18:26:34 ERROR (MainThread) [homeassistant] Error doing job: Task exception was never retrieved
Traceback (most recent call last):
  File "/usr/src/homeassistant/homeassistant/components/homekit_controller/connection.py", line 376, in async_update
    self.process_new_events(new_values_dict)
  File "/usr/src/homeassistant/homeassistant/components/homekit_controller/connection.py", line 393, in process_new_events
    self.entity_map.process_changes(new_values_dict)
  File "/usr/local/lib/python3.8/site-packages/aiohomekit/model/__init__.py", line 281, in process_changes
    accessory = self.aid(aid)
  File "/usr/local/lib/python3.8/site-packages/aiohomekit/model/__init__.py", line 277, in aid
    return next(filter(lambda accessory: accessory.aid == aid, self.accessories))
StopIteration

The above exception was the direct cause of the following exception:

RuntimeError: coroutine raised StopIteration
2020-11-20 18:27:34 ERROR (MainThread) [homeassistant] Error doing job: Task exception was never retrieved
Traceback (most recent call last):
  File "/usr/src/homeassistant/homeassistant/components/homekit_controller/connection.py", line 376, in async_update
    self.process_new_events(new_values_dict)
  File "/usr/src/homeassistant/homeassistant/components/homekit_controller/connection.py", line 393, in process_new_events
    self.entity_map.process_changes(new_values_dict)
  File "/usr/local/lib/python3.8/site-packages/aiohomekit/model/__init__.py", line 281, in process_changes
    accessory = self.aid(aid)
  File "/usr/local/lib/python3.8/site-packages/aiohomekit/model/__init__.py", line 277, in aid
    return next(filter(lambda accessory: accessory.aid == aid, self.accessories))
StopIteration

The above exception was the direct cause of the following exception:

RuntimeError: coroutine raised StopIteration
2020-11-20 18:28:34 ERROR (MainThread) [homeassistant] Error doing job: Task exception was never retrieved
Traceback (most recent call last):
  File "/usr/src/homeassistant/homeassistant/components/homekit_controller/connection.py", line 376, in async_update
    self.process_new_events(new_values_dict)
  File "/usr/src/homeassistant/homeassistant/components/homekit_controller/connection.py", line 393, in process_new_events
    self.entity_map.process_changes(new_values_dict)
  File "/usr/local/lib/python3.8/site-packages/aiohomekit/model/__init__.py", line 281, in process_changes
    accessory = self.aid(aid)
  File "/usr/local/lib/python3.8/site-packages/aiohomekit/model/__init__.py", line 277, in aid
    return next(filter(lambda accessory: accessory.aid == aid, self.accessories))
StopIteration

The above exception was the direct cause of the following exception:

RuntimeError: coroutine raised StopIteration
2020-11-20 18:29:08 ERROR (MainThread) [homeassistant.util.logging] Exception in async_write_ha_state when dispatching 'homekit_controller_30:D3:1B:A5:C8:D7_state_updated': ()
Traceback (most recent call last):
  File "/usr/src/homeassistant/homeassistant/helpers/entity.py", line 296, in async_write_ha_state
    self._async_write_ha_state()
  File "/usr/src/homeassistant/homeassistant/helpers/entity.py", line 320, in _async_write_ha_state
    sstate = self.state
  File "/usr/src/homeassistant/homeassistant/components/binary_sensor/__init__.py", line 158, in state
    return STATE_ON if self.is_on else STATE_OFF
  File "/usr/src/homeassistant/homeassistant/components/homekit_controller/binary_sensor.py", line 33, in is_on
    return self.service.value(CharacteristicsTypes.MOTION_DETECTED)
  File "/usr/src/homeassistant/homeassistant/components/homekit_controller/__init__.py", line 56, in service
    return self.accessory.services.iid(self._iid)
  File "/usr/src/homeassistant/homeassistant/components/homekit_controller/__init__.py", line 44, in accessory
    return self._accessory.entity_map.aid(self._aid)
  File "/usr/local/lib/python3.8/site-packages/aiohomekit/model/__init__.py", line 277, in aid
    return next(filter(lambda accessory: accessory.aid == aid, self.accessories))
StopIteration

2020-11-20 18:29:15 ERROR (MainThread) [homeassistant.util.logging] Exception in async_write_ha_state when dispatching 'homekit_controller_30:D3:1B:A5:C8:D7_state_updated': ()
Traceback (most recent call last):
  File "/usr/src/homeassistant/homeassistant/helpers/entity.py", line 296, in async_write_ha_state
    self._async_write_ha_state()
  File "/usr/src/homeassistant/homeassistant/helpers/entity.py", line 320, in _async_write_ha_state
    sstate = self.state
  File "/usr/src/homeassistant/homeassistant/components/binary_sensor/__init__.py", line 158, in state
    return STATE_ON if self.is_on else STATE_OFF
  File "/usr/src/homeassistant/homeassistant/components/homekit_controller/binary_sensor.py", line 33, in is_on
    return self.service.value(CharacteristicsTypes.MOTION_DETECTED)
  File "/usr/src/homeassistant/homeassistant/components/homekit_controller/__init__.py", line 56, in service
    return self.accessory.services.iid(self._iid)
  File "/usr/src/homeassistant/homeassistant/components/homekit_controller/__init__.py", line 44, in accessory
    return self._accessory.entity_map.aid(self._aid)
  File "/usr/local/lib/python3.8/site-packages/aiohomekit/model/__init__.py", line 277, in aid
    return next(filter(lambda accessory: accessory.aid == aid, self.accessories))
StopIteration

2020-11-20 18:29:15 ERROR (MainThread) [homeassistant.util.logging] Exception in async_write_ha_state when dispatching 'homekit_controller_30:D3:1B:A5:C8:D7_state_updated': ()
Traceback (most recent call last):
  File "/usr/src/homeassistant/homeassistant/helpers/entity.py", line 296, in async_write_ha_state
    self._async_write_ha_state()
  File "/usr/src/homeassistant/homeassistant/helpers/entity.py", line 320, in _async_write_ha_state
    sstate = self.state
  File "/usr/src/homeassistant/homeassistant/components/binary_sensor/__init__.py", line 158, in state
    return STATE_ON if self.is_on else STATE_OFF
  File "/usr/src/homeassistant/homeassistant/components/homekit_controller/binary_sensor.py", line 33, in is_on
    return self.service.value(CharacteristicsTypes.MOTION_DETECTED)
  File "/usr/src/homeassistant/homeassistant/components/homekit_controller/__init__.py", line 56, in service
    return self.accessory.services.iid(self._iid)
  File "/usr/src/homeassistant/homeassistant/components/homekit_controller/__init__.py", line 44, in accessory
    return self._accessory.entity_map.aid(self._aid)
  File "/usr/local/lib/python3.8/site-packages/aiohomekit/model/__init__.py", line 277, in aid
    return next(filter(lambda accessory: accessory.aid == aid, self.accessories))
StopIteration

2020-11-20 18:29:34 ERROR (MainThread) [homeassistant] Error doing job: Task exception was never retrieved
Traceback (most recent call last):
  File "/usr/src/homeassistant/homeassistant/components/homekit_controller/connection.py", line 376, in async_update
    self.process_new_events(new_values_dict)
  File "/usr/src/homeassistant/homeassistant/components/homekit_controller/connection.py", line 393, in process_new_events
    self.entity_map.process_changes(new_values_dict)
  File "/usr/local/lib/python3.8/site-packages/aiohomekit/model/__init__.py", line 281, in process_changes
    accessory = self.aid(aid)
  File "/usr/local/lib/python3.8/site-packages/aiohomekit/model/__init__.py", line 277, in aid
    return next(filter(lambda accessory: accessory.aid == aid, self.accessories))
StopIteration

The above exception was the direct cause of the following exception:

RuntimeError: coroutine raised StopIteration
2020-11-20 18:29:45 ERROR (MainThread) [homeassistant.util.logging] Exception in async_write_ha_state when dispatching 'homekit_controller_30:D3:1B:A5:C8:D7_state_updated': ()
Traceback (most recent call last):
  File "/usr/src/homeassistant/homeassistant/helpers/entity.py", line 296, in async_write_ha_state
    self._async_write_ha_state()
  File "/usr/src/homeassistant/homeassistant/helpers/entity.py", line 320, in _async_write_ha_state
    sstate = self.state
  File "/usr/src/homeassistant/homeassistant/components/binary_sensor/__init__.py", line 158, in state
    return STATE_ON if self.is_on else STATE_OFF
  File "/usr/src/homeassistant/homeassistant/components/homekit_controller/binary_sensor.py", line 33, in is_on
    return self.service.value(CharacteristicsTypes.MOTION_DETECTED)
  File "/usr/src/homeassistant/homeassistant/components/homekit_controller/__init__.py", line 56, in service
    return self.accessory.services.iid(self._iid)
  File "/usr/src/homeassistant/homeassistant/components/homekit_controller/__init__.py", line 44, in accessory
    return self._accessory.entity_map.aid(self._aid)
  File "/usr/local/lib/python3.8/site-packages/aiohomekit/model/__init__.py", line 277, in aid
    return next(filter(lambda accessory: accessory.aid == aid, self.accessories))
StopIteration

2020-11-20 18:29:45 ERROR (MainThread) [homeassistant.util.logging] Exception in async_write_ha_state when dispatching 'homekit_controller_30:D3:1B:A5:C8:D7_state_updated': ()
Traceback (most recent call last):
  File "/usr/src/homeassistant/homeassistant/helpers/entity.py", line 296, in async_write_ha_state
    self._async_write_ha_state()
  File "/usr/src/homeassistant/homeassistant/helpers/entity.py", line 320, in _async_write_ha_state
    sstate = self.state
  File "/usr/src/homeassistant/homeassistant/components/binary_sensor/__init__.py", line 158, in state
    return STATE_ON if self.is_on else STATE_OFF
  File "/usr/src/homeassistant/homeassistant/components/homekit_controller/binary_sensor.py", line 33, in is_on
    return self.service.value(CharacteristicsTypes.MOTION_DETECTED)
  File "/usr/src/homeassistant/homeassistant/components/homekit_controller/__init__.py", line 56, in service
    return self.accessory.services.iid(self._iid)
  File "/usr/src/homeassistant/homeassistant/components/homekit_controller/__init__.py", line 44, in accessory
    return self._accessory.entity_map.aid(self._aid)
  File "/usr/local/lib/python3.8/site-packages/aiohomekit/model/__init__.py", line 277, in aid
    return next(filter(lambda accessory: accessory.aid == aid, self.accessories))
StopIteration

2020-11-20 18:30:06 ERROR (MainThread) [homeassistant.util.logging] Exception in async_write_ha_state when dispatching 'homekit_controller_30:D3:1B:A5:C8:D7_state_updated': ()
Traceback (most recent call last):
  File "/usr/src/homeassistant/homeassistant/helpers/entity.py", line 296, in async_write_ha_state
    self._async_write_ha_state()
  File "/usr/src/homeassistant/homeassistant/helpers/entity.py", line 320, in _async_write_ha_state
    sstate = self.state
  File "/usr/src/homeassistant/homeassistant/components/binary_sensor/__init__.py", line 158, in state
    return STATE_ON if self.is_on else STATE_OFF
  File "/usr/src/homeassistant/homeassistant/components/homekit_controller/binary_sensor.py", line 33, in is_on
    return self.service.value(CharacteristicsTypes.MOTION_DETECTED)
  File "/usr/src/homeassistant/homeassistant/components/homekit_controller/__init__.py", line 56, in service
    return self.accessory.services.iid(self._iid)
  File "/usr/src/homeassistant/homeassistant/components/homekit_controller/__init__.py", line 44, in accessory
    return self._accessory.entity_map.aid(self._aid)
  File "/usr/local/lib/python3.8/site-packages/aiohomekit/model/__init__.py", line 277, in aid
    return next(filter(lambda accessory: accessory.aid == aid, self.accessories))
StopIteration

2020-11-20 18:30:34 ERROR (MainThread) [homeassistant] Error doing job: Task exception was never retrieved
Traceback (most recent call last):
  File "/usr/src/homeassistant/homeassistant/components/homekit_controller/connection.py", line 376, in async_update
    self.process_new_events(new_values_dict)
  File "/usr/src/homeassistant/homeassistant/components/homekit_controller/connection.py", line 393, in process_new_events
    self.entity_map.process_changes(new_values_dict)
  File "/usr/local/lib/python3.8/site-packages/aiohomekit/model/__init__.py", line 281, in process_changes
    accessory = self.aid(aid)
  File "/usr/local/lib/python3.8/site-packages/aiohomekit/model/__init__.py", line 277, in aid
    return next(filter(lambda accessory: accessory.aid == aid, self.accessories))
StopIteration

The above exception was the direct cause of the following exception:

RuntimeError: coroutine raised StopIteration
2020-11-20 18:31:34 ERROR (MainThread) [homeassistant] Error doing job: Task exception was never retrieved
Traceback (most recent call last):
  File "/usr/src/homeassistant/homeassistant/components/homekit_controller/connection.py", line 376, in async_update
    self.process_new_events(new_values_dict)
  File "/usr/src/homeassistant/homeassistant/components/homekit_controller/connection.py", line 393, in process_new_events
    self.entity_map.process_changes(new_values_dict)
  File "/usr/local/lib/python3.8/site-packages/aiohomekit/model/__init__.py", line 281, in process_changes
    accessory = self.aid(aid)
  File "/usr/local/lib/python3.8/site-packages/aiohomekit/model/__init__.py", line 277, in aid
    return next(filter(lambda accessory: accessory.aid == aid, self.accessories))
StopIteration

The above exception was the direct cause of the following exception:

RuntimeError: coroutine raised StopIteration
2020-11-20 18:32:19 ERROR (MainThread) [homeassistant.util.logging] Exception in async_write_ha_state when dispatching 'homekit_controller_30:D3:1B:A5:C8:D7_state_updated': ()
Traceback (most recent call last):
  File "/usr/src/homeassistant/homeassistant/helpers/entity.py", line 296, in async_write_ha_state
    self._async_write_ha_state()
  File "/usr/src/homeassistant/homeassistant/helpers/entity.py", line 320, in _async_write_ha_state
    sstate = self.state
  File "/usr/src/homeassistant/homeassistant/components/binary_sensor/__init__.py", line 158, in state
    return STATE_ON if self.is_on else STATE_OFF
  File "/usr/src/homeassistant/homeassistant/components/homekit_controller/binary_sensor.py", line 33, in is_on
    return self.service.value(CharacteristicsTypes.MOTION_DETECTED)
  File "/usr/src/homeassistant/homeassistant/components/homekit_controller/__init__.py", line 56, in service
    return self.accessory.services.iid(self._iid)
  File "/usr/src/homeassistant/homeassistant/components/homekit_controller/__init__.py", line 44, in accessory
    return self._accessory.entity_map.aid(self._aid)
  File "/usr/local/lib/python3.8/site-packages/aiohomekit/model/__init__.py", line 277, in aid
    return next(filter(lambda accessory: accessory.aid == aid, self.accessories))
StopIteration

2020-11-20 18:32:19 ERROR (MainThread) [homeassistant.util.logging] Exception in async_write_ha_state when dispatching 'homekit_controller_30:D3:1B:A5:C8:D7_state_updated': ()
Traceback (most recent call last):
  File "/usr/src/homeassistant/homeassistant/helpers/entity.py", line 296, in async_write_ha_state
    self._async_write_ha_state()
  File "/usr/src/homeassistant/homeassistant/helpers/entity.py", line 320, in _async_write_ha_state
    sstate = self.state
  File "/usr/src/homeassistant/homeassistant/components/binary_sensor/__init__.py", line 158, in state
    return STATE_ON if self.is_on else STATE_OFF
  File "/usr/src/homeassistant/homeassistant/components/homekit_controller/binary_sensor.py", line 33, in is_on
    return self.service.value(CharacteristicsTypes.MOTION_DETECTED)
  File "/usr/src/homeassistant/homeassistant/components/homekit_controller/__init__.py", line 56, in service
    return self.accessory.services.iid(self._iid)
  File "/usr/src/homeassistant/homeassistant/components/homekit_controller/__init__.py", line 44, in accessory
    return self._accessory.entity_map.aid(self._aid)
  File "/usr/local/lib/python3.8/site-packages/aiohomekit/model/__init__.py", line 277, in aid
    return next(filter(lambda accessory: accessory.aid == aid, self.accessories))
StopIteration

2020-11-20 18:32:19 ERROR (MainThread) [homeassistant.util.logging] Exception in async_write_ha_state when dispatching 'homekit_controller_30:D3:1B:A5:C8:D7_state_updated': ()
Traceback (most recent call last):
  File "/usr/src/homeassistant/homeassistant/helpers/entity.py", line 296, in async_write_ha_state
    self._async_write_ha_state()
  File "/usr/src/homeassistant/homeassistant/helpers/entity.py", line 320, in _async_write_ha_state
    sstate = self.state
  File "/usr/src/homeassistant/homeassistant/components/binary_sensor/__init__.py", line 158, in state
    return STATE_ON if self.is_on else STATE_OFF
  File "/usr/src/homeassistant/homeassistant/components/homekit_controller/binary_sensor.py", line 33, in is_on
    return self.service.value(CharacteristicsTypes.MOTION_DETECTED)
  File "/usr/src/homeassistant/homeassistant/components/homekit_controller/__init__.py", line 56, in service
    return self.accessory.services.iid(self._iid)
  File "/usr/src/homeassistant/homeassistant/components/homekit_controller/__init__.py", line 44, in accessory
    return self._accessory.entity_map.aid(self._aid)
  File "/usr/local/lib/python3.8/site-packages/aiohomekit/model/__init__.py", line 277, in aid
    return next(filter(lambda accessory: accessory.aid == aid, self.accessories))
StopIteration

2020-11-20 18:32:29 ERROR (MainThread) [homeassistant.util.logging] Exception in async_write_ha_state when dispatching 'homekit_controller_30:D3:1B:A5:C8:D7_state_updated': ()
Traceback (most recent call last):
  File "/usr/src/homeassistant/homeassistant/helpers/entity.py", line 296, in async_write_ha_state
    self._async_write_ha_state()
  File "/usr/src/homeassistant/homeassistant/helpers/entity.py", line 320, in _async_write_ha_state
    sstate = self.state
  File "/usr/src/homeassistant/homeassistant/components/binary_sensor/__init__.py", line 158, in state
    return STATE_ON if self.is_on else STATE_OFF
  File "/usr/src/homeassistant/homeassistant/components/homekit_controller/binary_sensor.py", line 33, in is_on
    return self.service.value(CharacteristicsTypes.MOTION_DETECTED)
  File "/usr/src/homeassistant/homeassistant/components/homekit_controller/__init__.py", line 56, in service
    return self.accessory.services.iid(self._iid)
  File "/usr/src/homeassistant/homeassistant/components/homekit_controller/__init__.py", line 44, in accessory
    return self._accessory.entity_map.aid(self._aid)
  File "/usr/local/lib/python3.8/site-packages/aiohomekit/model/__init__.py", line 277, in aid
    return next(filter(lambda accessory: accessory.aid == aid, self.accessories))
StopIteration

2020-11-20 18:32:34 ERROR (MainThread) [homeassistant] Error doing job: Task exception was never retrieved
Traceback (most recent call last):
  File "/usr/src/homeassistant/homeassistant/components/homekit_controller/connection.py", line 376, in async_update
    self.process_new_events(new_values_dict)
  File "/usr/src/homeassistant/homeassistant/components/homekit_controller/connection.py", line 393, in process_new_events
    self.entity_map.process_changes(new_values_dict)
  File "/usr/local/lib/python3.8/site-packages/aiohomekit/model/__init__.py", line 281, in process_changes
    accessory = self.aid(aid)
  File "/usr/local/lib/python3.8/site-packages/aiohomekit/model/__init__.py", line 277, in aid
    return next(filter(lambda accessory: accessory.aid == aid, self.accessories))
StopIteration

The above exception was the direct cause of the following exception:

RuntimeError: coroutine raised StopIteration
2020-11-20 18:33:19 ERROR (MainThread) [homeassistant.util.logging] Exception in async_write_ha_state when dispatching 'homekit_controller_30:D3:1B:A5:C8:D7_state_updated': ()
Traceback (most recent call last):
  File "/usr/src/homeassistant/homeassistant/helpers/entity.py", line 296, in async_write_ha_state
    self._async_write_ha_state()
  File "/usr/src/homeassistant/homeassistant/helpers/entity.py", line 320, in _async_write_ha_state
    sstate = self.state
  File "/usr/src/homeassistant/homeassistant/components/binary_sensor/__init__.py", line 158, in state
    return STATE_ON if self.is_on else STATE_OFF
  File "/usr/src/homeassistant/homeassistant/components/homekit_controller/binary_sensor.py", line 33, in is_on
    return self.service.value(CharacteristicsTypes.MOTION_DETECTED)
  File "/usr/src/homeassistant/homeassistant/components/homekit_controller/__init__.py", line 56, in service
    return self.accessory.services.iid(self._iid)
  File "/usr/src/homeassistant/homeassistant/components/homekit_controller/__init__.py", line 44, in accessory
    return self._accessory.entity_map.aid(self._aid)
  File "/usr/local/lib/python3.8/site-packages/aiohomekit/model/__init__.py", line 277, in aid
    return next(filter(lambda accessory: accessory.aid == aid, self.accessories))
StopIteration

2020-11-20 18:33:24 ERROR (MainThread) [homeassistant.util.logging] Exception in async_write_ha_state when dispatching 'homekit_controller_30:D3:1B:A5:C8:D7_state_updated': ()
Traceback (most recent call last):
  File "/usr/src/homeassistant/homeassistant/helpers/entity.py", line 296, in async_write_ha_state
    self._async_write_ha_state()
  File "/usr/src/homeassistant/homeassistant/helpers/entity.py", line 320, in _async_write_ha_state
    sstate = self.state
  File "/usr/src/homeassistant/homeassistant/components/binary_sensor/__init__.py", line 158, in state
    return STATE_ON if self.is_on else STATE_OFF
  File "/usr/src/homeassistant/homeassistant/components/homekit_controller/binary_sensor.py", line 33, in is_on
    return self.service.value(CharacteristicsTypes.MOTION_DETECTED)
  File "/usr/src/homeassistant/homeassistant/components/homekit_controller/__init__.py", line 56, in service
    return self.accessory.services.iid(self._iid)
  File "/usr/src/homeassistant/homeassistant/components/homekit_controller/__init__.py", line 44, in accessory
    return self._accessory.entity_map.aid(self._aid)
  File "/usr/local/lib/python3.8/site-packages/aiohomekit/model/__init__.py", line 277, in aid
    return next(filter(lambda accessory: accessory.aid == aid, self.accessories))
StopIteration

2020-11-20 18:33:24 ERROR (MainThread) [homeassistant.util.logging] Exception in async_write_ha_state when dispatching 'homekit_controller_30:D3:1B:A5:C8:D7_state_updated': ()
Traceback (most recent call last):
  File "/usr/src/homeassistant/homeassistant/helpers/entity.py", line 296, in async_write_ha_state
    self._async_write_ha_state()
  File "/usr/src/homeassistant/homeassistant/helpers/entity.py", line 320, in _async_write_ha_state
    sstate = self.state
  File "/usr/src/homeassistant/homeassistant/components/binary_sensor/__init__.py", line 158, in state
    return STATE_ON if self.is_on else STATE_OFF
  File "/usr/src/homeassistant/homeassistant/components/homekit_controller/binary_sensor.py", line 33, in is_on
    return self.service.value(CharacteristicsTypes.MOTION_DETECTED)
  File "/usr/src/homeassistant/homeassistant/components/homekit_controller/__init__.py", line 56, in service
    return self.accessory.services.iid(self._iid)
  File "/usr/src/homeassistant/homeassistant/components/homekit_controller/__init__.py", line 44, in accessory
    return self._accessory.entity_map.aid(self._aid)
  File "/usr/local/lib/python3.8/site-packages/aiohomekit/model/__init__.py", line 277, in aid
    return next(filter(lambda accessory: accessory.aid == aid, self.accessories))
StopIteration

2020-11-20 18:33:29 ERROR (MainThread) [homeassistant.util.logging] Exception in async_write_ha_state when dispatching 'homekit_controller_30:D3:1B:A5:C8:D7_state_updated': ()
Traceback (most recent call last):
  File "/usr/src/homeassistant/homeassistant/helpers/entity.py", line 296, in async_write_ha_state
    self._async_write_ha_state()
  File "/usr/src/homeassistant/homeassistant/helpers/entity.py", line 320, in _async_write_ha_state
    sstate = self.state
  File "/usr/src/homeassistant/homeassistant/components/binary_sensor/__init__.py", line 158, in state
    return STATE_ON if self.is_on else STATE_OFF
  File "/usr/src/homeassistant/homeassistant/components/homekit_controller/binary_sensor.py", line 33, in is_on
    return self.service.value(CharacteristicsTypes.MOTION_DETECTED)
  File "/usr/src/homeassistant/homeassistant/components/homekit_controller/__init__.py", line 56, in service
    return self.accessory.services.iid(self._iid)
  File "/usr/src/homeassistant/homeassistant/components/homekit_controller/__init__.py", line 44, in accessory
    return self._accessory.entity_map.aid(self._aid)
  File "/usr/local/lib/python3.8/site-packages/aiohomekit/model/__init__.py", line 277, in aid
    return next(filter(lambda accessory: accessory.aid == aid, self.accessories))
StopIteration

2020-11-20 18:33:34 ERROR (MainThread) [homeassistant] Error doing job: Task exception was never retrieved
Traceback (most recent call last):
  File "/usr/src/homeassistant/homeassistant/components/homekit_controller/connection.py", line 376, in async_update
    self.process_new_events(new_values_dict)
  File "/usr/src/homeassistant/homeassistant/components/homekit_controller/connection.py", line 393, in process_new_events
    self.entity_map.process_changes(new_values_dict)
  File "/usr/local/lib/python3.8/site-packages/aiohomekit/model/__init__.py", line 281, in process_changes
    accessory = self.aid(aid)
  File "/usr/local/lib/python3.8/site-packages/aiohomekit/model/__init__.py", line 277, in aid
    return next(filter(lambda accessory: accessory.aid == aid, self.accessories))
StopIteration

The above exception was the direct cause of the following exception:

RuntimeError: coroutine raised StopIteration
2020-11-20 18:34:34 ERROR (MainThread) [homeassistant] Error doing job: Task exception was never retrieved
Traceback (most recent call last):
  File "/usr/src/homeassistant/homeassistant/components/homekit_controller/connection.py", line 376, in async_update
    self.process_new_events(new_values_dict)
  File "/usr/src/homeassistant/homeassistant/components/homekit_controller/connection.py", line 393, in process_new_events
    self.entity_map.process_changes(new_values_dict)
  File "/usr/local/lib/python3.8/site-packages/aiohomekit/model/__init__.py", line 281, in process_changes
    accessory = self.aid(aid)
  File "/usr/local/lib/python3.8/site-packages/aiohomekit/model/__init__.py", line 277, in aid
    return next(filter(lambda accessory: accessory.aid == aid, self.accessories))
StopIteration

The above exception was the direct cause of the following exception:

RuntimeError: coroutine raised StopIteration
2020-11-20 18:35:34 ERROR (MainThread) [homeassistant] Error doing job: Task exception was never retrieved
Traceback (most recent call last):
  File "/usr/src/homeassistant/homeassistant/components/homekit_controller/connection.py", line 376, in async_update
    self.process_new_events(new_values_dict)
  File "/usr/src/homeassistant/homeassistant/components/homekit_controller/connection.py", line 393, in process_new_events
    self.entity_map.process_changes(new_values_dict)
  File "/usr/local/lib/python3.8/site-packages/aiohomekit/model/__init__.py", line 281, in process_changes
    accessory = self.aid(aid)
  File "/usr/local/lib/python3.8/site-packages/aiohomekit/model/__init__.py", line 277, in aid
    return next(filter(lambda accessory: accessory.aid == aid, self.accessories))
StopIteration

The above exception was the direct cause of the following exception:

RuntimeError: coroutine raised StopIteration
2020-11-20 18:36:34 ERROR (MainThread) [homeassistant] Error doing job: Task exception was never retrieved
Traceback (most recent call last):
  File "/usr/src/homeassistant/homeassistant/components/homekit_controller/connection.py", line 376, in async_update
    self.process_new_events(new_values_dict)
  File "/usr/src/homeassistant/homeassistant/components/homekit_controller/connection.py", line 393, in process_new_events
    self.entity_map.process_changes(new_values_dict)
  File "/usr/local/lib/python3.8/site-packages/aiohomekit/model/__init__.py", line 281, in process_changes
    accessory = self.aid(aid)
  File "/usr/local/lib/python3.8/site-packages/aiohomekit/model/__init__.py", line 277, in aid
    return next(filter(lambda accessory: accessory.aid == aid, self.accessories))
StopIteration

The above exception was the direct cause of the following exception:

RuntimeError: coroutine raised StopIteration
2020-11-20 18:37:34 ERROR (MainThread) [homeassistant] Error doing job: Task exception was never retrieved
Traceback (most recent call last):
  File "/usr/src/homeassistant/homeassistant/components/homekit_controller/connection.py", line 376, in async_update
    self.process_new_events(new_values_dict)
  File "/usr/src/homeassistant/homeassistant/components/homekit_controller/connection.py", line 393, in process_new_events
    self.entity_map.process_changes(new_values_dict)
  File "/usr/local/lib/python3.8/site-packages/aiohomekit/model/__init__.py", line 281, in process_changes
    accessory = self.aid(aid)
  File "/usr/local/lib/python3.8/site-packages/aiohomekit/model/__init__.py", line 277, in aid
    return next(filter(lambda accessory: accessory.aid == aid, self.accessories))
StopIteration

The above exception was the direct cause of the following exception:

RuntimeError: coroutine raised StopIteration
2020-11-20 18:38:34 ERROR (MainThread) [homeassistant] Error doing job: Task exception was never retrieved
Traceback (most recent call last):
  File "/usr/src/homeassistant/homeassistant/components/homekit_controller/connection.py", line 376, in async_update
    self.process_new_events(new_values_dict)
  File "/usr/src/homeassistant/homeassistant/components/homekit_controller/connection.py", line 393, in process_new_events
    self.entity_map.process_changes(new_values_dict)
  File "/usr/local/lib/python3.8/site-packages/aiohomekit/model/__init__.py", line 281, in process_changes
    accessory = self.aid(aid)
  File "/usr/local/lib/python3.8/site-packages/aiohomekit/model/__init__.py", line 277, in aid
    return next(filter(lambda accessory: accessory.aid == aid, self.accessories))
StopIteration

The above exception was the direct cause of the following exception:

RuntimeError: coroutine raised StopIteration
